[2025-04-01T22:06:21.477+0000] {taskinstance.py:1159} INFO - Dependencies all met for dep_context=non-requeueable deps ti=<TaskInstance: etl_web_scraper.load_data manual__2025-04-01T22:06:18.736552+00:00 [queued]>
[2025-04-01T22:06:21.481+0000] {taskinstance.py:1159} INFO - Dependencies all met for dep_context=requeueable deps ti=<TaskInstance: etl_web_scraper.load_data manual__2025-04-01T22:06:18.736552+00:00 [queued]>
[2025-04-01T22:06:21.481+0000] {taskinstance.py:1361} INFO - Starting attempt 1 of 1
[2025-04-01T22:06:21.487+0000] {taskinstance.py:1382} INFO - Executing <Task(PythonOperator): load_data> on 2025-04-01 22:06:18.736552+00:00
[2025-04-01T22:06:21.490+0000] {standard_task_runner.py:57} INFO - Started process 181 to run task
[2025-04-01T22:06:21.492+0000] {standard_task_runner.py:84} INFO - Running: ['***', 'tasks', 'run', 'etl_web_scraper', 'load_data', 'manual__2025-04-01T22:06:18.736552+00:00', '--job-id', '6', '--raw', '--subdir', 'DAGS_FOLDER/etl_web_scraper.py', '--cfg-path', '/tmp/tmpo209yjn2']
[2025-04-01T22:06:21.493+0000] {standard_task_runner.py:85} INFO - Job 6: Subtask load_data
[2025-04-01T22:06:21.500+0000] {logging_mixin.py:151} WARNING - /home/***/.local/lib/python3.8/site-packages/***/settings.py:193 DeprecationWarning: The sql_alchemy_conn option in [core] has been moved to the sql_alchemy_conn option in [database] - the old setting has been used, but please update your config.
[2025-04-01T22:06:21.514+0000] {task_command.py:416} INFO - Running <TaskInstance: etl_web_scraper.load_data manual__2025-04-01T22:06:18.736552+00:00 [running]> on host cf88f1e7a14e
[2025-04-01T22:06:21.542+0000] {taskinstance.py:1662} INFO - Exporting env vars: AIRFLOW_CTX_DAG_OWNER='***' AIRFLOW_CTX_DAG_ID='etl_web_scraper' AIRFLOW_CTX_TASK_ID='load_data' AIRFLOW_CTX_EXECUTION_DATE='2025-04-01T22:06:18.736552+00:00' AIRFLOW_CTX_TRY_NUMBER='1' AIRFLOW_CTX_DAG_RUN_ID='manual__2025-04-01T22:06:18.736552+00:00'
[2025-04-01T22:06:21.564+0000] {taskinstance.py:1937} ERROR - Task failed with exception
Traceback (most recent call last):
  File "/home/airflow/.local/lib/python3.8/site-packages/airflow/operators/python.py", line 192, in execute
    return_value = self.execute_callable()
  File "/home/airflow/.local/lib/python3.8/site-packages/airflow/operators/python.py", line 209, in execute_callable
    return self.python_callable(*self.op_args, **self.op_kwargs)
  File "/opt/airflow/dags/etl_web_scraper.py", line 39, in <lambda>
    load_task = PythonOperator(task_id="load_data", python_callable=lambda **context: load(context["ti"].xcom_pull(task_ids="transform_data")), provide_context=True)
  File "/opt/airflow/dags/etl_web_scraper.py", line 24, in load
    cur.execute("CREATE TABLE IF NOT EXISTS posts (id INTEGER PRIMARY KEY, title TEXT);")
psycopg2.errors.UniqueViolation: duplicate key value violates unique constraint "pg_type_typname_nsp_index"
DETAIL:  Key (typname, typnamespace)=(posts, 2200) already exists.

[2025-04-01T22:06:21.569+0000] {taskinstance.py:1400} INFO - Marking task as FAILED. dag_id=etl_web_scraper, task_id=load_data, execution_date=20250401T220618, start_date=20250401T220621, end_date=20250401T220621
[2025-04-01T22:06:21.574+0000] {standard_task_runner.py:104} ERROR - Failed to execute job 6 for task load_data (duplicate key value violates unique constraint "pg_type_typname_nsp_index"
DETAIL:  Key (typname, typnamespace)=(posts, 2200) already exists.
; 181)
[2025-04-01T22:06:21.590+0000] {local_task_job_runner.py:228} INFO - Task exited with return code 1
[2025-04-01T22:06:21.598+0000] {taskinstance.py:2778} INFO - 0 downstream tasks scheduled from follow-on schedule check
